{"name": "test_fun_01", "status": "failed", "statusDetails": {"message": "AssertionError: assert 4 == 5\n +  where 4 = fun(1)", "trace": "@pytest.mark.usefixtures(\"function_no_return_fixture\")\n    def test_fun_01():\n        print(\"我是第二个测试函数\");\n>       assert fun(1) ==5;\nE       assert 4 == 5\nE        +  where 4 = fun(1)\n\ntest_case.py:54: AssertionError"}, "attachments": [{"name": "stdout", "source": "11156dc2-9f60-4fe6-ba9b-067f85d7f0eb-attachment.txt", "type": "text/plain"}], "start": 1610630976908, "stop": 1610630976908, "uuid": "84ed7408-771d-40b7-9ea3-74c268898944", "historyId": "889aba88ac156d81da8970ed1159bfe9", "testCaseId": "ab13344ecb0b651588b61abebdabcea7", "fullName": "test_case#test_fun_01", "labels": [{"name": "tag", "value": "@pytest.mark.usefixtures('function_no_return_fixture')"}, {"name": "suite", "value": "test_case"}, {"name": "host", "value": "yantianpeng.local"}, {"name": "thread", "value": "28074-MainThread"}, {"name": "framework", "value": "pytest"}, {"name": "language", "value": "cpython3"}, {"name": "package", "value": "test_case"}]}