{"name": "test_fun_01", "status": "failed", "statusDetails": {"message": "AssertionError: assert 4 == 5\n +  where 4 = fun(1)", "trace": "@pytest.mark.usefixtures(\"function_no_return_fixture\")\n    def test_fun_01():\n        print(\"我是第二个测试函数\");\n>       assert fun(1) ==5;\nE       assert 4 == 5\nE        +  where 4 = fun(1)\n\ntest_case.py:54: AssertionError"}, "start": 1610631530495, "stop": 1610631530495, "uuid": "f4915811-41a8-49ad-89d6-4575cd8adc8e", "historyId": "889aba88ac156d81da8970ed1159bfe9", "testCaseId": "ab13344ecb0b651588b61abebdabcea7", "fullName": "test_case#test_fun_01", "labels": [{"name": "tag", "value": "@pytest.mark.usefixtures('function_no_return_fixture')"}, {"name": "suite", "value": "test_case"}, {"name": "host", "value": "yantianpeng.local"}, {"name": "thread", "value": "28373-MainThread"}, {"name": "framework", "value": "pytest"}, {"name": "language", "value": "cpython3"}, {"name": "package", "value": "test_case"}]}