{"name": "test_fun_01", "status": "failed", "statusDetails": {"message": "AssertionError: assert 4 == 5\n +  where 4 = fun(1)", "trace": "@pytest.mark.usefixtures(\"function_no_return_fixture\")\n    def test_fun_01():\n        print(\"我是第二个测试函数\");\n>       assert fun(1) ==5;\nE       assert 4 == 5\nE        +  where 4 = fun(1)\n\ntest_case.py:54: AssertionError"}, "start": 1610631584043, "stop": 1610631584044, "uuid": "1d825dc2-c59e-46c6-ae3b-42cee334d47a", "historyId": "889aba88ac156d81da8970ed1159bfe9", "testCaseId": "ab13344ecb0b651588b61abebdabcea7", "fullName": "test_case#test_fun_01", "labels": [{"name": "tag", "value": "@pytest.mark.usefixtures('function_no_return_fixture')"}, {"name": "suite", "value": "test_case"}, {"name": "host", "value": "yantianpeng.local"}, {"name": "thread", "value": "28416-MainThread"}, {"name": "framework", "value": "pytest"}, {"name": "language", "value": "cpython3"}, {"name": "package", "value": "test_case"}]}